{"channel":"book","type":"snapshot","data":[{"symbol":"ETH/USD","bids":[{"price":2690.69,"qty":2.04278393},{"price":2690.58,"qty":0.55754046},{"price":2690.57,"qty":0.20000000},{"price":2690.55,"qty":0.55471963},{"price":2690.54,"qty":1.85835721},{"price":2690.40,"qty":0.24630428},{"price":2690.36,"qty":0.00181818},{"price":2690.35,"qty":2.21938540},{"price":2690.34,"qty":7.43512697},{"price":2690.22,"qty":15.38430460}],"asks":[{"price":2690.70,"qty":0.11349169},{"price":2690.71,"qty":0.36062264},{"price":2690.79,"qty":0.00800000},{"price":2690.81,"qty":0.57352937},{"price":2690.84,"qty":0.00800000},{"price":2690.86,"qty":2.72761216},{"price":2690.87,"qty":9.49326706},{"price":2690.91,"qty":1.10538593},{"price":2690.92,"qty":0.96075878},{"price":2691.00,"qty":0.25883828}],"checksum":47606189,"timestamp":"2026-09-26T08:31:15.895700Z"}]}
{"channel":"book","type":"update","data":[{"symbol":"ETH/USD","bids":[{"price":2690.23,"qty":27.87411665}],"asks":[],"checksum":472473011,"timestamp":"2026-09-26T08:31:16.006064Z"}]}
{"channel":"book","type":"update","data":[{"symbol":"ETH/USD","bids":[{"price":2690.35,"qty":10.25606517}],"asks":[],"checksum":1543772930,"timestamp":"2026-09-26T08:31:16.006722Z"}]}
{"channel":"book","type":"update","data":[{"symbol":"ETH/USD","bids":[{"price":2690.23,"qty":0.00000000},{"price":2690.20,"qty":0.37171957}],"asks":[],"checksum":1362620076,"timestamp":"2026-09-26T08:31:16.153477Z"}]}
{"channel":"book","type":"update","data":[{"symbol":"ETH/USD","bids":[{"price":2690.21,"qty":27.87413644}],"asks":[],"checksum":3947903068,"timestamp":"2026-09-26T08:31:16.153477Z"}]}
{"channel":"book","type":"update","data":[{"symbol":"ETH/USD","bids":[{"price":2690.35,"qty":2.21938540}],"asks":[],"checksum":2877128429,"timestamp":"2026-09-26T08:31:16.154459Z"}]}
{"channel":"book","type":"update","data":[{"symbol":"ETH/USD","bids":[{"price":2690.22,"qty":15.54265642}],"asks":[],"checksum":4123148737,"timestamp":"2026-09-26T08:31:16.155178Z"}]}
{"channel":"book","type":"update","data":[{"symbol":"ETH/USD","bids":[{"price":2690.23,"qty":27.87415968}],"asks":[],"checksum":3869700452,"timestamp":"2026-09-26T08:31:17.005590Z"}]}
{"channel":"book","type":"update","data":[{"symbol":"ETH/USD","bids":[{"price":2690.35,"qty":10.25607802}],"asks":[],"checksum":2522854769,"timestamp":"2026-09-26T08:31:17.007245Z"}]}
{"channel":"book","type":"update","data":[{"symbol":"ETH/USD","bids":[{"price":2690.23,"qty":0.00000000},{"price":2690.20,"qty":0.37171957}],"asks":[],"checksum":3347436146,"timestamp":"2026-09-26T08:31:17.149943Z"}]}
{"channel":"book","type":"update","data":[{"symbol":"ETH/USD","bids":[{"price":2690.21,"qty":27.87415977}],"asks":[],"checksum":1201086560,"timestamp":"2026-09-26T08:31:17.149943Z"}]}
{"channel":"book","type":"update","data":[{"symbol":"ETH/USD","bids":[{"price":2690.35,"qty":2.21938540}],"asks":[],"checksum":929981557,"timestamp":"2026-09-26T08:31:17.150631Z"}]}
{"channel":"book","type":"update","data":[{"symbol":"ETH/USD","bids":[{"price":2690.22,"qty":15.54266338}],"asks":[],"checksum":1311265565,"timestamp":"2026-09-26T08:31:17.211685Z"}]}
{"channel":"book","type":"update","data":[{"symbol":"ETH/USD","bids":[],"asks":[{"price":2690.86,"qty":0.00800000}],"checksum":2316125856,"timestamp":"2026-09-26T08:31:17.640617Z"}]}
{"channel":"book","type":"update","data":[{"symbol":"ETH/USD","bids":[],"asks":[{"price":2690.87,"qty":2.05814009}],"checksum":644070255,"timestamp":"2026-09-26T08:31:17.643915Z"}]}
{"channel":"book","type":"update","data":[{"symbol":"ETH/USD","bids":[{"price":2690.34,"qty":0.00000000},{"price":2690.21,"qty":27.87415977}],"asks":[],"checksum":66178329,"timestamp":"2026-09-26T08:31:17.644572Z"}]}
{"channel":"book","type":"update","data":[{"symbol":"ETH/USD","bids":[{"price":2690.35,"qty":0.00000000},{"price":2690.20,"qty":0.37171957}],"asks":[],"checksum":19789115,"timestamp":"2026-09-26T08:31:17.645552Z"}]}
{"channel":"book","type":"update","data":[{"symbol":"ETH/USD","bids":[{"price":2690.41,"qty":7.43512697}],"asks":[],"checksum":747966762,"timestamp":"2026-09-26T08:31:17.649973Z"}]}
{"channel":"book","type":"update","data":[{"symbol":"ETH/USD","bids":[{"price":2690.54,"qty":0.00000000},{"price":2690.20,"qty":0.37171957}],"asks":[],"checksum":1686645630,"timestamp":"2026-09-26T08:31:17.650762Z"}]}
{"channel":"book","type":"update","data":[{"symbol":"ETH/USD","bids":[{"price":2690.42,"qty":2.29344995}],"asks":[],"checksum":2196608353,"timestamp":"2026-09-26T08:31:17.651336Z"}]}
{"channel":"book","type":"update","data":[{"symbol":"ETH/USD","bids":[{"price":2690.55,"qty":0.00000000},{"price":2690.20,"qty":0.37171957}],"asks":[],"checksum":3798809962,"timestamp":"2026-09-26T08:31:17.651530Z"}]}
{"channel":"book","type":"update","data":[{"symbol":"ETH/USD","bids":[{"price":2690.66,"qty":1.85827383}],"asks":[],"checksum":2709186612,"timestamp":"2026-09-26T08:31:17.651569Z"}]}
{"channel":"book","type":"update","data":[{"symbol":"ETH/USD","bids":[{"price":2690.67,"qty":0.55469474}],"asks":[],"checksum":2006690675,"timestamp":"2026-09-26T08:31:17.652677Z"}]}
{"channel":"book","type":"update","data":[{"symbol":"ETH/USD","bids":[{"price":2690.58,"qty":0.00000000},{"price":2690.21,"qty":27.87415977}],"asks":[],"checksum":2200666879,"timestamp":"2026-09-26T08:31:17.652795Z"}]}
{"channel":"book","type":"update","data":[{"symbol":"ETH/USD","bids":[{"price":2690.67,"qty":1.11223520}],"asks":[],"checksum":1642050344,"timestamp":"2026-09-26T08:31:17.652795Z"}]}
{"channel":"book","type":"update","data":[{"symbol":"ETH/USD","bids":[{"price":2690.41,"qty":0.00000000},{"price":2690.20,"qty":0.37171957}],"asks":[],"checksum":4193169243,"timestamp":"2026-09-26T08:31:17.654532Z"}]}
{"channel":"book","type":"update","data":[{"symbol":"ETH/USD","bids":[{"price":2690.42,"qty":0.00000000},{"price":2690.18,"qty":18.58611269}],"asks":[],"checksum":1766066762,"timestamp":"2026-09-26T08:31:17.655101Z"}]}
{"channel":"book","type":"update","data":[{"symbol":"ETH/USD","bids":[{"price":2690.21,"qty":0.00000000},{"price":2690.17,"qty":4.16367111}],"asks":[],"checksum":2830872520,"timestamp":"2026-09-26T08:31:17.656559Z"}]}
{"channel":"book","type":"update","data":[{"symbol":"ETH/USD","bids":[{"price":2690.41,"qty":27.87415851}],"asks":[],"checksum":2634292069,"timestamp":"2026-09-26T08:31:17.656559Z"}]}
{"channel":"book","type":"update","data":[{"symbol":"ETH/USD","bids":[{"price":2690.22,"qty":0.00000000},{"price":2690.17,"qty":4.16367111}],"asks":[],"checksum":1458063056,"timestamp":"2026-09-26T08:31:17.657202Z"}]}
{"channel":"book","type":"update","data":[{"symbol":"ETH/USD","bids":[{"price":2690.42,"qty":8.39450087}],"asks":[],"checksum":1100805558,"timestamp":"2026-09-26T08:31:17.657307Z"}]}
{"channel":"book","type":"update","data":[{"symbol":"ETH/USD","bids":[{"price":2690.19,"qty":7.11126840}],"asks":[],"checksum":529366453,"timestamp":"2026-09-26T08:31:17.658114Z"}]}
{"channel":"book","type":"update","data":[{"symbol":"ETH/USD","bids":[{"price":2690.47,"qty":7.43512697}],"asks":[],"checksum":1085824301,"timestamp":"2026-09-26T08:31:17.659894Z"}]}
{"channel":"book","type":"update","data":[{"symbol":"ETH/USD","bids":[],"asks":[{"price":2690.87,"qty":0.20000000}],"checksum":3804682341,"timestamp":"2026-09-26T08:31:17.661021Z"}]}
{"channel":"book","type":"update","data":[{"symbol":"ETH/USD","bids":[{"price":2690.47,"qty":0.00000000},{"price":2690.19,"qty":7.11126840}],"asks":[],"checksum":3186882813,"timestamp":"2026-09-26T08:31:17.662072Z"}]}
{"channel":"book","type":"update","data":[{"symbol":"ETH/USD","bids":[{"price":2690.51,"qty":7.43512697}],"asks":[],"checksum":2622665803,"timestamp":"2026-09-26T08:31:17.693249Z"}]}
{"channel":"book","type":"update","data":[{"symbol":"ETH/USD","bids":[{"price":2690.52,"qty":2.21938540}],"asks":[],"checksum":4140832754,"timestamp":"2026-09-26T08:31:17.694373Z"}]}
{"channel":"book","type":"update","data":[{"symbol":"ETH/USD","bids":[{"price":2690.51,"qty":0.00000000},{"price":2690.20,"qty":0.37171957}],"asks":[],"checksum":631768036,"timestamp":"2026-09-26T08:31:17.694947Z"}]}
{"channel":"book","type":"update","data":[{"symbol":"ETH/USD","bids":[{"price":2690.52,"qty":0.00000000},{"price":2690.19,"qty":7.11126840}],"asks":[],"checksum":3186882813,"timestamp":"2026-09-26T08:31:17.695856Z"}]}
{"channel":"book","type":"update","data":[{"symbol":"ETH/USD","bids":[],"asks":[{"price":2691.00,"qty":0.00000000},{"price":2691.01,"qty":1.85804397}],"checksum":2143494907,"timestamp":"2026-09-26T08:31:17.706738Z"}]}
{"channel":"book","type":"update","data":[{"symbol":"ETH/USD","bids":[{"price":2690.49,"qty":7.43512697}],"asks":[],"checksum":1341102098,"timestamp":"2026-09-26T08:31:17.707118Z"}]}
